<?xml version="1.0" ?>
<robot name="test_robot">

  <link name="base_link">
    <visual>
      <origin xyz="0 0 0.1" rpy="0 0 1.5708"/>
      <geometry>
        <mesh filename="Chassis_Top.stl" scale="0.001 0.001 0.001"/>
      </geometry>
    </visual>
    <collision>
      <origin xyz="0 0 0.1" rpy="0 0 1.5708"/>
      <geometry>
        <mesh filename="Chassis_Top.stl" scale="0.001 0.001 0.001"/>
      </geometry>
    </collision>
    <inertial>
      <mass value="1"/>
      <origin xyz="0 0 0" rpy="0 0 0"/>
      <inertia ixx="0.001" ixy="0" ixz="0" iyy="0.001" iyz="0" izz="0.001"/>
    </inertial>
  </link>

  <visual>
    <origin xyz="0 0 0" rpy="0 0 0"/>
    <geometry>
      <sphere radius="0.005"/>
    </geometry>
  </visual>

  <!-- Coxa links -->
  <link name="coxa_1">
    <visual>
      <origin xyz="0.050 0.055 0.055" rpy="0 0.7854 1.5708"/>
      <geometry>
        <mesh filename="Coxa_Top.stl" scale="0.001 0.001 0.001"/>
      </geometry>
    </visual>
    <collision>
      <origin xyz="0.050 0.055 0.055" rpy="0 0.7854 1.5708"/>
      <geometry>
        <mesh filename="Coxa_Top.stl" scale="0.001 0.001 0.001"/>
      </geometry>
    </collision>
    <inertial>
      <mass value="0.01"/>
      <origin xyz="0 0 0" rpy="0 0 0"/>
      <inertia ixx="0.0001" ixy="0" ixz="0" iyy="0.0001" iyz="0" izz="0.0001"/>
    </inertial>
  </link>


  <link name="coxa_2">
    <visual>
      <origin xyz="0.050 0.055 -0.055" rpy="0 2.3562 1.5708"/>
      <geometry>
        <mesh filename="Coxa_Top.stl" scale="0.001 0.001 0.001"/>
      </geometry>
    </visual>
    <collision>
      <origin xyz="0.050 0.055 -0.055" rpy="0 2.3562 1.5708"/>
      <geometry>
        <mesh filename="Coxa_Top.stl" scale="0.001 0.001 0.001"/>
      </geometry>
    </collision>
    <inertial>
      <mass value="0.01"/>
      <origin xyz="0 0 0" rpy="0 0 0"/>
      <inertia ixx="0.0001" ixy="0" ixz="0" iyy="0.0001" iyz="0" izz="0.0001"/>
    </inertial>
  </link>



  <link name="coxa_3">
    <visual>
      <origin xyz="0.050 -0.055 -0.055" rpy="0 -2.3562 1.5708"/>
      <geometry>
        <mesh filename="Coxa_Top.stl" scale="0.001 0.001 0.001"/>
      </geometry>
    </visual>
    <collision>
      <origin xyz="0.050 -0.055 -0.055" rpy="0 -2.3562 1.5708"/>
      <geometry>
        <mesh filename="Coxa_Top.stl" scale="0.001 0.001 0.001"/>
      </geometry>
    </collision>
    <inertial>
      <mass value="0.01"/>
      <origin xyz="0 0 0" rpy="0 0 0"/>
      <inertia ixx="0.0001" ixy="0" ixz="0" iyy="0.0001" iyz="0" izz="0.0001"/>
    </inertial>
  </link>




  <link name="coxa_4">
    <visual>
      <origin xyz="0.050 -0.055 0.055" rpy="0 -0.7854 1.5708"/>
      <geometry>
        <mesh filename="Coxa_Top.stl" scale="0.001 0.001 0.001"/>
      </geometry>
    </visual>
    <collision>
      <origin xyz="0.050 -0.055 0.055" rpy="0 -0.7854 1.5708"/>
      <geometry>
        <mesh filename="Coxa_Top.stl" scale="0.001 0.001 0.001"/>
      </geometry>
    </collision>
    <inertial>
      <mass value="0.01"/>
      <origin xyz="0 0 0" rpy="0 0 0"/>
      <inertia ixx="0.0001" ixy="0" ixz="0" iyy="0.0001" iyz="0" izz="0.0001"/>
    </inertial>
  </link>

    

  <link name="femur_1">
    <visual>
      <origin xyz="0 0 0" rpy="0 -0.7854 1.5708"/>
      <geometry>
        <mesh filename="Femur_Frontplate.stl" scale="0.001 0.001 0.001"/>
      </geometry>
    </visual>
    <collision>
      <origin xyz="0.065 0.010 -0.015" rpy="0 -0.7854 1.5708"/>
      <geometry>
        <mesh filename="Femur_Frontplate.stl" scale="0.001 0.001 0.001"/>
      </geometry>
    </collision>
    <inertial>
      <mass value="0.01"/>
      <origin xyz="0 0 0"/>
      <inertia ixx="0.00005" ixy="0" ixz="0" iyy="0.00005" iyz="0" izz="0.00005"/>
    </inertial>
  </link>


  <link name="femur_2">
    <visual>
      <origin xyz="0 0 0" rpy="0 -2.3562 1.5708"/>
      <geometry>
        <mesh filename="Femur_Frontplate.stl" scale="0.001 0.001 0.001"/>
      </geometry>
    </visual>
    <collision>
      <origin xyz="0.065 0.015 -0.015" rpy="0 -2.3562 1.5708"/>
      <geometry>
        <mesh filename="Femur_Frontplate.stl" scale="0.001 0.001 0.001"/>
      </geometry>
    </collision>
    <inertial>
      <mass value="0.01"/>
      <origin xyz="0 0 0"/>
      <inertia ixx="0.00005" ixy="0" ixz="0" iyy="0.00005" iyz="0" izz="0.00005"/>
    </inertial>
  </link>

<link name="femur_3">
  <visual>
    <origin xyz="0 0 0" rpy="0 2.3562 1.5708"/>
    <geometry>
      <mesh filename="Femur_Frontplate_x.stl" scale="0.001 0.001 0.001"/>
    </geometry>
  </visual>
  <collision>
    <origin xyz="0.065 -0.022 -0.015" rpy="0 2.3562 1.5708"/>
    <geometry>
      <mesh filename="Femur_Frontplate_x.stl" scale="0.001 0.001 0.001"/>
    </geometry>
  </collision>
  <inertial>
    <mass value="0.01"/>
    <origin xyz="0 0 0"/>
    <inertia ixx="0.00005" ixy="0" ixz="0" iyy="0.00005" iyz="0" izz="0.00005"/>
  </inertial>
</link>

<link name="femur_4">
  <visual>
    <origin xyz="0 0 0" rpy="0 0.7854 1.5708"/>
    <geometry>
      <mesh filename="Femur_Frontplate_x.stl" scale="0.001 0.001 0.001"/>
    </geometry>
  </visual>
  <collision>
    <origin xyz="0.065 -0.022 -0.015" rpy="0 0.7854 1.5708"/>
    <geometry>
      <mesh filename="Femur_Frontplate_x.stl" scale="0.001 0.001 0.001"/>
    </geometry>
  </collision>
  <inertial>
    <mass value="0.01"/>
    <origin xyz="0 0 0"/>
    <inertia ixx="0.00005" ixy="0" ixz="0" iyy="0.00005" iyz="0" izz="0.00005"/>
  </inertial>
</link>



<link name="tibia_1">
  <visual>
    <origin xyz="0.015 0.025 0.025" rpy="0 -0.7854 1.5708"/>
    <geometry>
      <mesh filename="Tibia.stl" scale="0.001 0.001 0.001"/>
    </geometry>
  </visual>
  <collision>
    <origin xyz="0.015 0.025 0.025" rpy="0 -0.7854 1.5708"/>
    <geometry>
      <mesh filename="Tibia.stl" scale="0.001 0.001 0.001"/>
    </geometry>
  </collision>
  <inertial>
    <mass value="0.01"/>
    <origin xyz="0 0 0"/>
    <inertia ixx="0.00005" ixy="0" ixz="0" iyy="0.00005" iyz="0" izz="0.00005"/>
  </inertial>
</link>


<link name="tibia_2">
  <visual>
    <origin xyz="0.015 -0.025 0.025" rpy="0 -2.3562 1.5708"/>
    <geometry>
      <mesh filename="Tibia.stl" scale="0.001 0.001 0.001"/>
    </geometry>
  </visual>
  <collision>
    <origin xyz="0.015 -0.025 0.025" rpy="0 -2.3562 1.5708"/>
    <geometry>
      <mesh filename="Tibia.stl" scale="0.001 0.001 0.001"/>
    </geometry>
  </collision>
  <inertial>
    <mass value="0.01"/>
    <origin xyz="0 0 0"/>
    <inertia ixx="0.00005" ixy="0" ixz="0" iyy="0.00005" iyz="0" izz="0.00005"/>
  </inertial>
</link>


<link name="tibia_3">
  <visual>
    <origin xyz="0.015 0.025 0.025" rpy="0 -0.7854 1.5708"/>
    <geometry>
      <mesh filename="Tibia.stl" scale="0.001 0.001 0.001"/>
    </geometry>
  </visual>
  <collision>
    <origin xyz="0.015 0.025 0.025" rpy="0 -0.7854 1.5708"/>
    <geometry>
      <mesh filename="Tibia.stl" scale="0.001 0.001 0.001"/>
    </geometry>
  </collision>
  <inertial>
    <mass value="0.01"/>
    <origin xyz="0 0 0"/>
    <inertia ixx="0.00005" ixy="0" ixz="0" iyy="0.00005" iyz="0" izz="0.00005"/>
  </inertial>
</link>


<link name="tibia_4">
  <visual>
    <origin xyz="0.015 -0.025 0.025" rpy="0 -2.3562 1.5708"/>
    <geometry>
      <mesh filename="Tibia.stl" scale="0.001 0.001 0.001"/>
    </geometry>
  </visual>
  <collision>
    <origin xyz="0.015 -0.025 0.025" rpy="0 -2.3562 1.5708"/>
    <geometry>
      <mesh filename="Tibia.stl" scale="0.001 0.001 0.001"/>
    </geometry>
  </collision>
  <inertial>
    <mass value="0.01"/>
    <origin xyz="0 0 0"/>
    <inertia ixx="0.00005" ixy="0" ixz="0" iyy="0.00005" iyz="0" izz="0.00005"/>
  </inertial>
</link>


  <!-- Revolute joint -->
  <joint name="joint_coxa_1" type="revolute">
    <parent link="base_link"/>
    <child link="coxa_1"/>
    <origin xyz="0 0.070 0.170" rpy="0 0 0"/>
    <axis xyz="1 0 0"/>
    <limit lower="-1.57" upper="1.57" effort="1.0" velocity="1.0"/>
  </joint>

  <!-- Zmieniono typ jointu coxa_2 i pozycję oraz oś -->
  <joint name="joint_coxa_2" type="revolute">
    <parent link="base_link"/>
    <child link="coxa_2"/>
    <origin xyz="0 0.070 0.030" rpy="0 0 0"/>
    <axis xyz="1 0 0"/>
    <limit lower="-1.57" upper="1.57" effort="1.0" velocity="1.0"/>
  </joint>

  <joint name="joint_coxa_3" type="revolute">
    <parent link="base_link"/>
    <child link="coxa_3"/>
    <origin xyz="0.0 -0.07 0.030" rpy="0 0 0"/>
    <axis xyz="1 0 0"/>
    <limit lower="-1.57" upper="1.57" effort="1.0" velocity="1.0"/>
  </joint>

  <joint name="joint_coxa_4" type="revolute">
    <parent link="base_link"/>
    <child link="coxa_4"/>
    <origin xyz="0.0 -0.07 0.170" rpy="0 0 0"/>
    <axis xyz="1 0 0"/>
    <limit lower="-1.57" upper="1.57" effort="1.0" velocity="1.0"/>
  </joint>

<joint name="joint_femur_1" type="revolute">
  <parent link="coxa_1"/>
  <child link="femur_1"/>
  <origin xyz="0.055 0.055 0.055" rpy="0 0 0"/>
  <axis xyz="0 1 -1"/> <!-- zgina w dół i do wewnątrz, jak kolano -->
  <limit lower="-1.57" upper="1.57" effort="1.0" velocity="1.0"/>
</joint>

<joint name="joint_femur_2" type="revolute">
  <parent link="coxa_2"/>
  <child link="femur_2"/>
  <origin xyz="0.055 0.055 -0.055" rpy="3.1416 0 0"/>
  <axis xyz="0 -1 -1"/> <!-- odbicie w osi Y i ruch do środka -->
  <limit lower="-1.57" upper="1.57" effort="1.0" velocity="1.0"/>
</joint>

<joint name="joint_femur_3" type="revolute">
  <parent link="coxa_3"/>
  <child link="femur_3"/>
  <origin xyz="0.055 -0.055 -0.055" rpy="3.1416 0 0"/> <!-- ⬅️ dolna, przeciwna noga -->
  <axis xyz="0 1 -1"/>
  <limit lower="-1.57" upper="1.57" effort="1.0" velocity="1.0"/>
</joint>

<joint name="joint_femur_4" type="revolute">
  <parent link="coxa_4"/>
  <child link="femur_4"/>
  <origin xyz="0.055 -0.055 0.055" rpy="0 0 0"/>
  <axis xyz="0 -1 -1"/> <!-- jak lustrzane odbicie joint_femur_1 -->
  <limit lower="-1.57" upper="1.57" effort="1.0" velocity="1.0"/>
</joint>

<joint name="joint_tibia_1" type="revolute">
  <parent link="femur_1"/>
  <child link="tibia_1"/>
  <origin xyz="0 0.08 0.08" rpy="0 0 0"/> <!-- zakładam, że tibia zaczyna się 6.5cm od początku femura -->
  <axis xyz="0 1 -1"/> <!-- zgięcie w dół (jak kolano) -->
  <limit lower="-1.57" upper="1.57" effort="1.0" velocity="1.0"/>
</joint>

<joint name="joint_tibia_2" type="revolute">
  <parent link="femur_2"/>
  <child link="tibia_2"/>
  <origin xyz="0 -0.08 0.08" rpy="0 0 0"/>
  <axis xyz="0 -1 -1"/>
  <limit lower="-1.57" upper="1.57" effort="1.0" velocity="1.0"/>
</joint>

<joint name="joint_tibia_3" type="revolute">
  <parent link="femur_3"/>
  <child link="tibia_3"/>
  <origin xyz="0 0.08 0.08" rpy="0 0 0"/>
  <axis xyz="0 1 -1"/>
  <limit lower="-1.57" upper="1.57" effort="1.0" velocity="1.0"/>
</joint>

<joint name="joint_tibia_4" type="revolute">
  <parent link="femur_4"/>
  <child link="tibia_4"/>
  <origin xyz="0 -0.08 0.08" rpy="0 0 0"/>
  <axis xyz="0 -1 -1"/>
  <limit lower="-1.57" upper="1.57" effort="1.0" velocity="1.0"/>
</joint>

</robot>
